Workbook

Sheet 0. Intro
B1: English
B2: ='12.lan'!D4 -> BALANCE SHEET CALCULATOR | M2: =IF('12.lan'!B2="","",'12.lan'!B2) -> Select your language
B3: ='12.lan'!D6 -> Version | C3: 5.06 | M3: =IF('12.lan'!B3="","",'12.lan'!B3) -> Deutsch
M4: =IF('12.lan'!B4="","",'12.lan'!B4) -> Italiano
B5: ='12.lan'!D7 -> WELCOME! | M5: =IF('12.lan'!B5="","",'12.lan'!B5) -> English
B6: ='12.lan'!D8 -> This tool is for calculating the overall Common Good Points for your company or organisation. It complements the Common Good Report and has to be used together with it. Have fun with your calculation! | M6: =IF('12.lan'!B6="","",'12.lan'!B6) -> Español
M7: =IF('12.lan'!B7="","",'12.lan'!B7) -> Francais
B8: ='12.lan'!D9 -> HOW TO USE THE BALANCE SHEET CALCULATOR: | M8: =IF('12.lan'!B8="","",'12.lan'!B8)
B9: ='12.lan'!D10 -> 1. General | D9: ='12.lan'!D11 -> You can enter general information about your company or organisation in this section. | M9: =IF('12.lan'!B9="","",'12.lan'!B9)
B10: ='12.lan'!D28 -> 2. Company details | D10: ='12.lan'!D12 -> All fields in this section must be completed as they are essential for the weighting of each theme. | M10: =IF('12.lan'!B10="","",'12.lan'!B10)
B11: ='12.lan'!D29 -> 3. Scoring | D11: ='12.lan'!D13 -> For each theme (A1, B1, ...) a certain maximum number of Common Good Points can be achieved. To evaluate how many points your company scores, follow these steps: | M11: =IF('12.lan'!B11="","",'12.lan'!B11)
B12: a) | D12: ='12.lan'!D14 -> Describe the current status and potential for improvement for the various aspects under key headings. Use the workbook as a reference. (This is optional and not absolutely necessary for the calculation.) | M12: =IF('12.lan'!B12="","",'12.lan'!B12)
B13: b) | D13: ='12.lan'!D15 -> Based on these descriptions, indicate on a scale of 0-10 how far you consider the respective aspect is met (Achievement level). The criteria for choosing the correct value can be found in the Workbook.
B14: c) | D14: ='12.lan'!D16 -> Negative aspects are allocated negative points according to the descriptions set out in the Workbook.
B15: d) | D15: ='12.lan'!D17 -> Where deemed necessary for your company and in agreement with the auditors you can change the relative weightings of individual aspects (A1.1, A1.2, ..). In the column Weighting, you can select values for each aspect. The distribution of available points for individual aspects will then be adjusted automatically, so that the total of all aspects of an indicator result in 100%.
B16: e) | D16: ='12.lan'!D18 -> The calculation automatically weights each theme’s total value against the data in the ‘Company details’ section and rounds it to a whole-number multiple of 10%.
B17: f) | D17: ='12.lan'!D45 -> The format of the numbers is usually rounded to facilitate the visualization but the numbers are not actually rounded. You may see for example that an aspect is 1 (real value 1,3) and other 1 (real value 1,4) but the sum of the two aspects is 3 (real value 2,7)
B18: ='12.lan'!D30 -> 4. ECG Matrix | D18: ='12.lan'!D19 -> The ECG-Matrix displays your result in a table.
B19: ='12.lan'!D31 -> 5. Values star | D19: ='12.lan'!D21 -> The values-star displays your result arranged by value as a graphic.
B20: ='12.lan'!D32 -> 6. Group star | D20: ='12.lan'!D22 -> The group-star displays your result arranged by stakeholder as a graphic.
B21: ='12.lan'!D33 -> 7. Theme star | D21: ='12.lan'!D23 -> The theme-star displays the result of your themes as a graphic.
B22: ='12.lan'!D34 -> 8. Weighting model description | D22: ='12.lan'!D24 -> This is a description of the weighting model.
B23: ='12.lan'!D35 -> 9. Weighting (hidden) | D23: ='12.lan'!D25 -> This is where the calculation determines how the individual stakeholder groups and themes are weighted.
B24: ='12.lan'!D36 -> 10. Industry sectors (hidden) | D24: ='12.lan'!D26 -> This contains an assessment of the relevance of supply chains and environmental sustainability for all industry sectors, used in the weighting.
B25: ='12.lan'!D37 -> 11. Countries (hidden) | D25: ='12.lan'!D27 -> This contains statistics for countries and regions used in the weighting.
B27: ='12.lan'!D40 -> KEY
B28: ='12.lan'!D41 -> Field is editable (green frame, dark green text)
B30: ='12.lan'!D42 -> Feld is read-only (grey frame, dark grey text)
B32: ='12.lan'!D43 -> non valid value entry (for correct calculation change value)
B34: ='12.lan'!D54 -> CONTACT
B35: ='12.lan'!D55 -> Questions regarding preparation of balance sheet: beratung@gemeinwohl-oekonomie.org (GWÖ-BeraterInnen);
B36: ='12.lan'!D56 -> Questions regarding audit: audit@gemeinwohl-oekonomie.org (GWÖ-AuditorInnen);
B37: ='12.lan'!D57 -> Feedback on the development of the Matrix: bilanz@ecogood.org (Matrix Development Team)
B38: ='12.lan'!D58 -> Excel programming: Christian Loy (christian.loy@gmx.at); Christian Kozina; Multilanguage tool: Bernhard Oberrauch
B39: ='12.lan'!D59 -> Contents: ECG-Matrix Development Team
B41: ='12.lan'!D60 -> NOTES
B42: ='12.lan'!D61 -> All sheets are optimised for printing on A4 format (landscape or portrait). The height of rows can be adjusted, if you enter more text The format of the numbers is usually rounded to facilitate the visualization but the numbers are not actually rounded. You may see as an example that an aspect is 1 (actually 1,3) and other 1 (actually 1,4) but the sum is 3 (actually 2,7).

Sheet 1. General
B2: ='12.lan'!D91&" - "&'0. Intro'!B3&" "&'0. Intro'!C3 -> Common Good Balance Calculator - Version 5.06
B3: ='12.lan'!D62 -> GENERAL INFORMATION ABOUT THE COMPANY
B4: ='12.lan'!D63 -> Please complete all fields.
B6: ='12.lan'!D64 -> Name of Company / Organisation: | C6: LuftGewinn
B7: ='12.lan'!D65 -> Address: | C7: , , 45456
B8: ='12.lan'!D66 -> Country: | C8: Deutschland
B9: ='12.lan'!D67 -> Industry sector:
B10: ='12.lan'!D68 -> Website: | C10: www.a.qq
B12: ='12.lan'!D83 -> Period under review | C12: 01.01.2019 - 31.12.2019
B14: ='12.lan'!D73 -> Document created by: | C14: N. nachar
B15: ='12.lan'!D74 -> Email address: | C15: nachar@gmx.net
B16: ='12.lan'!D75 -> Phone number:
B18: ='12.lan'!D76 -> Consultant:
B19: ='12.lan'!D74 -> Email address:
B20: ='12.lan'!D75 -> Phone number:
B22: ='12.lan'!D79 -> Short description of Company / Organisation | C22: gggg
B24: ='12.lan'!D80 -> Additional comments:

Sheet 2. Company Facts
B2: ='12.lan'!D91&" - "&'0. Intro'!B3&" "&'0. Intro'!C3 -> Common Good Balance Calculator - Version 5.06 | M2: ='12.lan'!D52 -> yes
B3: ='12.lan'!D194 -> Company details | M3: ='12.lan'!D53 -> no
B4: ='12.lan'!D195 -> Fill in the highlighted fields below. Where detailed information is not available, please enter estimates, otherwise the calculation will not be accurate
B6: ='12.lan'!B108 -> A: Suppliers
B7: ='12.lan'!D297 -> Total purchases from suppliers (in Euros): | C7: 200000 | D7: =IF(SUM(F10:F14)>C7,'12.lan'!D44,"")
B8: ='12.lan'!D298 -> Enter the 5 most important industry sectors whose products or services you use.
B9: ='12.lan'!D299 -> Industry sector | C9: ='12.lan'!D300 -> Description | D9: ='12.lan'!D301 -> Region of origin | F9: ='12.lan'!D302 -> Costs
B10: A - Landwirtschaft, Forstwirtschaft und Fischerei | D10: EGY Ägypten | F10: 3388
B11: Ca - Food production, drinks and tobacco (C10, C11, C12) | D11: AFG Afghanistan | F11: 654
B12: A - Landwirtschaft, Forstwirtschaft und Fischerei | D12: DZA Algerien | F12: 456
B13: A - Landwirtschaft, Forstwirtschaft und Fischerei | D13: BGD Bangladesch | F13: 77
B14: Please enter | F14: 0
B15: ='12.lan'!$D$303 -> Main origin of the other suppliers | D15: QAT Katar | F15: =C7-F10-F11-F12-F13-F14 -> 195425
B17: ='12.lan'!B122 -> B: Owners, equity- and financial service providers
B18: ='12.lan'!D304 -> Profit | C18: 456456456
B19: ='12.lan'!D305 -> Financing costs | C19: 266
B20: ='12.lan'!D306 -> Income from financial investments | C20: 500
B21: ='12.lan'!D307 -> Total assets | C21: 420
B22: ='12.lan'!D308 -> Additions to fixed-assets | C22: 400
B23: ='12.lan'!D309 -> Financial assets and cash balance | C23: 310
B25: ='12.lan'!B137 -> C: Employees
B26: ='12.lan'!D310 -> Number of employees (full time equivalents) | C26: 5
B27: ='12.lan'!D311 -> Staff costs (gross without employer contribution) | C27: 5501
B28: ='12.lan'!D312 -> Enter the 3 countries and regions where most of the staff are
B29: ='12.lan'!D313 -> Country and region | D29: ='12.lan'!D314 -> Amount in %
B30: ETH Äthiopien | D30: 0.46 | E30: =IF(SUM(D30:D32)>"100%","fehlerhafte Eingabe","")
B31: BHR Bahrain | D31: 0.11
D32: 0
B33: ='12.lan'!D315 -> Average journey to work for staff (in km) | C33: 456456
B34: ='12.lan'!D316 -> Is there a canteen for the majority of staff? | C34: no | D34: Ja | F34: Nein
B36: ='12.lan'!B158 -> D: Customers and other companies
B37: ='12.lan'!D317 -> Turnover (in Euros) | C37: 124
B38: ='12.lan'!D318 -> Are your customers mainly other companies? | C38: ja
B39: ='12.lan'!D319 -> Enter the 3 most important industry sectors which your company is active in, including a rough share of turnover
B40: ='12.lan'!D320 -> Industry sector | C40: ='12.lan'!D321 -> Description | D40: ='12.lan'!D322 -> % Amount of total turnover
B41: J - Information und Kommunikation | D41: 0.87 | F41: =IF(SUM(D41:D43)>"100%","fehlerhafte Eingabe","")
B42: Ce - Pharmaceutical products and preparations (C21) | C42: abc | D42: 0.13
B43: Please enter | D43: 0 | F43: =IF(SUM(D41:D43)>1,'12.lan'!D44,"")
B45: ='12.lan'!B175 -> E: Social environment
B46: ='12.lan'!D323 -> Company size | C46: ='9. Weighting'!H39 -> Micro-business

Sheet 3. Calc
B2: ='12.lan'!D91&" - "&'0. Intro'!B3&" "&'0. Intro'!C3 -> Common Good Balance Calculator - Version 5.06
B3: ='12.lan'!D90 -> CALCULATION OF INDIVIDUAL ASPECTS
F4: ='12.lan'!D92 -> Total Balance Score: | H4: =I4/J4 -> -0.38904762 | I4: =IF(SUM(I9+I23+I38+I59+I76)*1000/SUM(J9+J23+J38+J59+J76)<-3600,-3600,SUM(I9+I23+I38+I59+I76)*1000/SUM(J9+J23+J38+J59+J76)) -> -389.04762 | J4: =SUM(J9+J23+J38+J59+J76)*1000/SUM(J9+J23+J38+J59+J76) -> 1000 | L4: ausblenden | O4: ausblenben
B5: ='12.lan'!D82&": "&'1. General'!C6&"; "&'12.lan'!D83&": "&'1. General'!C12 -> Company / Organisation: LuftGewinn; Period under review: 01.01.2019 - 31.12.2019
B8: ='12.lan'!D93 -> No. | C8: ='12.lan'!D107 -> Stakeholders/ Themes/ Aspects | D8: ='12.lan'!D96 -> Weight | F8: ='12.lan'!D102 -> Current status | H8: ='12.lan'!D104 -> Est% | I8: ='12.lan'!D105 -> Points | J8: ='12.lan'!D106 -> Max. | L8: Gewichtung Standard | O8: Reset
B9: A | C9: ='12.lan'!D108 -> Suppliers | D9: =L9 -> 0.5 | E9: =VLOOKUP(D9,$C$102:$D$106,2,FALSE()) -> low | H9: =IFERROR(I9/J9,0) -> -0.875 | I9: =I10+I13+I17+I20 -> -83.333333 | J9: =J10+J13+J17+J20 -> 95.238095 | L9: ='9. Weighting'!K49 -> 0.5 | N9: =IF(D9<>L9,'12.lan'!$D$240&VLOOKUP(L9,$C$102:$D$106,2,FALSE())&" ("&L9&")","")
B10: A1 | C10: ='12.lan'!D109 -> Human dignity in the supply chain | D10: =IF(K10="trifft nicht zu",C106,'9. Weighting'!M16) -> 1 | E10: =VLOOKUP(D10,$C$102:$D$106,2,FALSE()) -> medium | F10: ='9. Weighting'!M16 -> 1 | H10: =IF(J10<>0,SUM(I11:I12)/J10,"-") -> -1.8 | I10: =IF(J10=0,0,H10*J10) -> -42.857143 | J10: ='9. Weighting'!M15 -> 23.809524 | L10: =VLOOKUP(O10,$C$102:$E$106,3,FALSE()) -> 1 | M10: =VLOOKUP(D10,$C$102:$E$106,3,FALSE()) -> 1 | N10: =IF(L10=M10,"",'12.lan'!$D$240&VLOOKUP(L10,$C$102:$D$106,2,FALSE())&" ("&L10&")") | O10: =IF(K10="trifft nicht zu",C106,'9. Weighting'!M16) -> 1
B11: A1.1 | C11: ='12.lan'!D110 -> Working conditions and social impact in the supply chain | F11: ='12.lan'!$D$329 -> Introduce value between 0 and 10 | H11: 2 | I11: =J11*H11/10 -> 4.7619048 | J11: =J10*K11/K11 -> 23.809524 | K11: 1 | N11: =IF(L11=M11,"",'12.lan'!$D$240&" "&VLOOKUP(L11,$C$102:$D$106,2,FALSE())&" ("&L11&")")
B12: A1.2 | C12: ='12.lan'!D111 -> Negative aspect: violation of human dignity in the supply chain | F12: ='12.lan'!$D$330 -> Introduce negative points between 0 and -200 | H12: -100 | I12: =H12*J10/50 -> -47.619048 | J12: =-200*J10/50 -> -95.238095
B13: A2 | C13: ='12.lan'!D112 -> Solidarity and social justice in the supply chain | D13: =IF(K13="trifft nicht zu",C106,'9. Weighting'!N16) -> 1 | E13: =VLOOKUP(D13,$C$102:$D$106,2,FALSE()) -> medium | F13: =IF(K13="trifft nicht zu","trifft nicht zu",'9. Weighting'!N16) -> 1 | H13: =IF(J13<>0,SUM(I14:I16)/J13,"-") -> -1.8 | I13: =IF(J13=0,0,H13*J13) -> -42.857143 | J13: ='9. Weighting'!N15 -> 23.809524 | K13: =IF(AND(D14="trifft nicht zu",D15="trifft nicht zu"),"trifft nicht zu","") | L13: =VLOOKUP(O13,$C$102:$E$106,3,FALSE()) -> 1 | M13: =VLOOKUP(D13,$C$102:$E$106,3,FALSE()) -> 1 | N13: =IF(L13=M13,"",'12.lan'!$D$240&VLOOKUP(L13,$C$102:$D$106,2,FALSE())&" ("&L13&")") | O13: =IF(K13="trifft nicht zu",C106,'9. Weighting'!N16) -> 1
B14: A2.1 | C14: ='12.lan'!D113 -> Fair business practices towards direct suppliers | D14: 1 | E14: =VLOOKUP(D14,$C$102:$D$106,2,FALSE()) -> medium | F14: ='12.lan'!$D$329 -> Introduce value between 0 and 10 | H14: 4 | I14: =IFERROR(J14*H14/10,0) -> 4.7619048 | J14: =IFERROR(J13*K14/(K15+K14),0) -> 11.904762 | K14: =VLOOKUP(D14,$C$102:$E$106,3,FALSE()) -> 1 | L14: =VLOOKUP(O14,$C$102:$E$106,3,FALSE()) -> 1 | M14: =VLOOKUP(D14,$C$102:$E$106,3,FALSE()) -> 1 | N14: =IF(L14=M14,"",'12.lan'!$D$240&VLOOKUP(L14,$C$102:$D$106,2,FALSE())&" ("&L14&")") | O14: =C104 -> 1
B15: A2.2 | C15: ='12.lan'!D114 -> Exercising a positive influence on solidarity and social justice in the supply chain | D15: =C104 -> 1 | E15: =VLOOKUP(D15,$C$102:$D$106,2,FALSE()) -> medium | F15: ='12.lan'!$D$329 -> Introduce value between 0 and 10 | I15: =IFERROR(J15*H15/10,0) -> 0 | J15: =IFERROR(J13*K15/(K14+K15),0) -> 11.904762 | K15: =VLOOKUP(D15,$C$102:$E$106,3,FALSE()) -> 1 | L15: =VLOOKUP(O15,$C$102:$E$106,3,FALSE()) -> 1 | M15: =VLOOKUP(D15,$C$102:$E$106,3,FALSE()) -> 1 | N15: =IF(L15=M15,"",'12.lan'!$D$240&VLOOKUP(L15,$C$102:$D$106,2,FALSE())&" ("&L15&")") | O15: =C104 -> 1
B16: A2.3 | C16: ='12.lan'!D115 -> Negative aspect: abuse of market power against suppliers | F16: ='12.lan'!$D$330 -> Introduce negative points between 0 and -200 | H16: -100 | I16: =H16*J13/50 -> -47.619048 | J16: =-200*J13/50 -> -95.238095
B17: A3 | C17: ='12.lan'!D116 -> Environmental sustainability in the supply chain | D17: =IF(K17="trifft nicht zu",C106,'9. Weighting'!O16) -> 1 | E17: =VLOOKUP(D17,$C$102:$D$106,2,FALSE()) -> medium | F17: =IF(K17="trifft nicht zu","trifft nicht zu",'9. Weighting'!O16) -> 1 | H17: =IF(J17<>0,SUM(I18:I19)/J17,"-") -> 0.1 | I17: =IF(J17=0,0,H17*J17) -> 2.3809524 | J17: ='9. Weighting'!O15 -> 23.809524 | K17: =IF(D18="trifft nicht zu","trifft nicht zu","") | L17: =VLOOKUP(O17,$C$102:$E$106,3,FALSE()) -> 1 | M17: =VLOOKUP(D17,$C$102:$E$106,3,FALSE()) -> 1 | N17: =IF(L17=M17,"",'12.lan'!$D$240&VLOOKUP(L17,$C$102:$D$106,2,FALSE())&" ("&L17&")") | O17: =IF(K17="trifft nicht zu",C106,'9. Weighting'!O16) -> 1
B18: A3.1 | C18: ='12.lan'!D117 -> Environmental impact throughout the supply chain | F18: ='12.lan'!$D$329 -> Introduce value between 0 and 10 | H18: 1 | I18: =J18*H18/10 -> 2.3809524 | J18: =J17*K18/K18 -> 23.809524 | K18: 1 | N18: =IF(L18=M18,"",'12.lan'!$D$240&VLOOKUP(L18,$C$102:$D$106,2,FALSE())&" ("&L18&")")
B19: A3.2 | C19: ='12.lan'!D118 -> Negative aspect: disproportionate environmental impact throughout the supply chain | F19: ='12.lan'!$D$330 -> Introduce negative points between 0 and -200 | I19: =H19*J17/50 -> 0 | J19: =-200*J17/50 -> -95.238095
B20: A4 | C20: ='12.lan'!D119 -> Transparency & co-determination in the supply chain | D20: =IF(K20="trifft nicht zu",C106,'9. Weighting'!P16) -> 1 | E20: =VLOOKUP(D20,$C$102:$D$106,2,FALSE()) -> medium | F20: =IF(K20="trifft nicht zu","trifft nicht zu",'9. Weighting'!P16) -> 1 | H20: =IF(J20<>0,SUM(I21:I22)/J20,"-") -> 0 | I20: =IF(J20=0,0,H20*J20) -> 0 | J20: ='9. Weighting'!P15 -> 23.809524 | K20: =IF(AND(D21="trifft nicht zu",D22="trifft nicht zu"),"trifft nicht zu","") | L20: =VLOOKUP(O20,$C$102:$E$106,3,FALSE()) -> 1 | M20: =VLOOKUP(D20,$C$102:$E$106,3,FALSE()) -> 1 | N20: =IF(L20=M20,"",'12.lan'!$D$240&VLOOKUP(L20,$C$102:$D$106,2,FALSE())&" ("&L20&")") | O20: =IF(K20="trifft nicht zu",C106,'9. Weighting'!P16) -> 1
B21: A4.1 | C21: ='12.lan'!D120 -> Transparency towards suppliers and their right to co-determination | D21: =C104 -> 1 | E21: =VLOOKUP(D21,$C$102:$D$106,2,FALSE()) -> medium | F21: ='12.lan'!$D$329 -> Introduce value between 0 and 10 | I21: =IFERROR(J21*H21/10,0) -> 0 | J21: =IFERROR(J20*K21/(K22+K21),0) -> 11.904762 | K21: =VLOOKUP(D21,$C$102:$E$106,3,FALSE()) -> 1 | L21: =VLOOKUP(O21,$C$102:$E$106,3,FALSE()) -> 1 | M21: =VLOOKUP(D21,$C$102:$E$106,3,FALSE()) -> 1 | N21: =IF(L21=M21,"",'12.lan'!$D$240&VLOOKUP(L21,$C$102:$D$106,2,FALSE())&" ("&L21&")") | O21: =C104 -> 1
B22: A4.2 | C22: ='12.lan'!D121 -> Positive influence on transparency and co-determination throughout the supply chain | D22: =C104 -> 1 | E22: =VLOOKUP(D22,$C$102:$D$106,2,FALSE()) -> medium | F22: ='12.lan'!$D$329 -> Introduce value between 0 and 10 | I22: =IFERROR(J22*H22/10,0) -> 0 | J22: =IFERROR(J20*K22/(K21+K22),0) -> 11.904762 | K22: =VLOOKUP(D22,$C$102:$E$106,3,FALSE()) -> 1 | L22: =VLOOKUP(O22,$C$102:$E$106,3,FALSE()) -> 1 | M22: =VLOOKUP(D22,$C$102:$E$106,3,FALSE()) -> 1 | N22: =IF(L22=M22,"",'12.lan'!$D$240&VLOOKUP(L22,$C$102:$D$106,2,FALSE())&" ("&L22&")") | O22: =C104 -> 1
B23: B | C23: ='12.lan'!D122 -> Owners, equity- and financial service providers | D23: =L23 -> 2 | E23: =VLOOKUP(D23,$C$102:$D$106,2,FALSE()) -> very high | H23: =IFERROR(I23/J23,0) -> 0.037037037 | I23: =I24+I28+I31+I35 -> 15.873016 | J23: =J24+J28+J31+J35 -> 428.57143 | L23: ='9. Weighting'!K50 -> 2 | N23: =IF(D23<>L23,'12.lan'!$D$240&VLOOKUP(L23,$C$102:$D$106,2,FALSE())&" ("&L23&")","")
B24: B1 | C24: ='12.lan'!D123 -> Ethical position in relation to financial resources | D24: =IF(K24="trifft nicht zu",C106,'9. Weighting'!M24) -> 1 | E24: =VLOOKUP(D24,$C$102:$D$106,2,FALSE()) -> medium | F24: =IF(K24="trifft nicht zu","trifft nicht zu",'9. Weighting'!M24) -> 1 | H24: =IF(J24<>0,SUM(I25:I27)/J24,"-") -> 0.16666667 | I24: =IF(J24=0,0,H24*J24) -> 15.873016 | J24: ='9. Weighting'!M23 -> 95.238095 | K24: =IF(AND(D25="trifft nicht zu",D26="trifft nicht zu",,D27="trifft nicht zu"),"trifft nicht zu","") | L24: =VLOOKUP(O24,$C$102:$E$106,3,FALSE()) -> 1 | M24: =VLOOKUP(D24,$C$102:$E$106,3,FALSE()) -> 1 | N24: =IF(L24=M24,"",'12.lan'!$D$240&VLOOKUP(L24,$C$102:$D$106,2,FALSE())&" ("&L24&")") | O24: =IF(K24="trifft nicht zu",C106,'9. Weighting'!M24) -> 1
B25: B1.1 | C25: ='12.lan'!D124 -> Financial independence through equity financing | D25: =C104 -> 1 | E25: =VLOOKUP(D25,$C$102:$D$106,2,FALSE()) -> medium | F25: ='12.lan'!$D$329 -> Introduce value between 0 and 10 | H25: 0 | I25: =IFERROR(J25*H25/10,0) -> 0 | J25: =IFERROR($J$24*K25/($K$27+$K$26+$K$25),0) -> 31.746032 | K25: =VLOOKUP(D25,$C$102:$E$106,3,FALSE()) -> 1 | L25: =VLOOKUP(O25,$C$102:$E$106,3,FALSE()) -> 1 | M25: =VLOOKUP(D25,$C$102:$E$106,3,FALSE()) -> 1 | N25: =IF(L25=M25,"",'12.lan'!$D$240&VLOOKUP(L25,$C$102:$D$106,2,FALSE())&" ("&L25&")") | O25: =C104 -> 1
B26: B1.2 | C26: ='12.lan'!D125 -> Common Good-orientated borrowing | D26: =C104 -> 1 | E26: =VLOOKUP(D26,$C$102:$D$106,2,FALSE()) -> medium | F26: ='12.lan'!$D$329 -> Introduce value between 0 and 10 | H26: 5 | I26: =IFERROR(J26*H26/10,0) -> 15.873016 | J26: =IFERROR($J$24*K26/($K$27+$K$26+$K$25),0) -> 31.746032 | K26: =VLOOKUP(D26,$C$102:$E$106,3,FALSE()) -> 1 | L26: =VLOOKUP(O26,$C$102:$E$106,3,FALSE()) -> 1 | M26: =VLOOKUP(D26,$C$102:$E$106,3,FALSE()) -> 1 | N26: =IF(L26=M26,"",'12.lan'!$D$240&VLOOKUP(L26,$C$102:$D$106,2,FALSE())&" ("&L26&")") | O26: =C104 -> 1
B27: B1.3 | C27: ='12.lan'!D126 -> Ethical position of external financial partners | D27: =C104 -> 1 | E27: =VLOOKUP(D27,$C$102:$D$106,2,FALSE()) -> medium | F27: ='12.lan'!$D$329 -> Introduce value between 0 and 10 | H27: 0 | I27: =IFERROR(J27*H27/10,0) -> 0 | J27: =IFERROR($J$24*K27/($K$27+$K$26+$K$25),0) -> 31.746032 | K27: =VLOOKUP(D27,$C$102:$E$106,3,FALSE()) -> 1 | L27: =VLOOKUP(O27,$C$102:$E$106,3,FALSE()) -> 1 | M27: =VLOOKUP(D27,$C$102:$E$106,3,FALSE()) -> 1 | N27: =IF(L27=M27,"",'12.lan'!$D$240&VLOOKUP(L27,$C$102:$D$106,2,FALSE())&" ("&L27&")") | O27: =C104 -> 1
B28: B2 | C28: ='12.lan'!D127 -> Social position in relation to financial resources | D28: =IF(K28="trifft nicht zu",C106,'9. Weighting'!N24) -> 1.5 | E28: =VLOOKUP(D28,$C$102:$D$106,2,FALSE()) -> high | F28: =IF(K28="trifft nicht zu","trifft nicht zu",'9. Weighting'!N24) -> 1.5 | H28: =IF(J28<>0,SUM(I29:I30)/J28,"-") -> 0 | I28: =IF(J28=0,0,H28*J28) -> 0 | J28: ='9. Weighting'!N23 -> 142.85714 | L28: =VLOOKUP(O28,$C$102:$E$106,3,FALSE()) -> 1.5 | M28: =VLOOKUP(D28,$C$102:$E$106,3,FALSE()) -> 1.5 | N28: =IF(L28=M28,"",'12.lan'!$D$240&VLOOKUP(L28,$C$102:$D$106,2,FALSE())&" ("&L28&")") | O28: =IF(K28="trifft nicht zu",C106,'9. Weighting'!N24) -> 1.5
B29: B2.1 | C29: ='12.lan'!D128 -> Solidarity and Common Good-orientated use of funds | F29: ='12.lan'!$D$329 -> Introduce value between 0 and 10 | I29: =J29*H29/10 -> 0 | J29: =$J$28*K29/(K29) -> 142.85714 | K29: 1 | L29: =VLOOKUP(O29,$C$102:$E$106,3,FALSE()) -> #N/A | M29: =VLOOKUP(D29,$C$102:$E$106,3,FALSE()) -> #N/A
B30: B2.2 | C30: ='12.lan'!D129 -> Negative aspect: unfair distribution of funds | F30: ='12.lan'!$D$330 -> Introduce negative points between 0 and -200 | I30: =H30*J28/50 -> 0 | J30: =-200*J28/50 -> -571.42857
B31: B3 | C31: ='12.lan'!D130 -> Use of funds in relation to social and environmental impacts | D31: =IF(K31="trifft nicht zu",C106,'9. Weighting'!O24) -> 1.5 | E31: =VLOOKUP(D31,$C$102:$D$106,2,FALSE()) -> high | F31: =IF(K31="trifft nicht zu","trifft nicht zu",'9. Weighting'!O24) -> 1.5 | H31: =IF(J31<>0,SUM(I32:I34)/J31,"-") -> 0 | I31: =IF(J31=0,0,H31*J31) -> 0 | J31: ='9. Weighting'!O23 -> 142.85714 | K31: =IF(AND(D32="trifft nicht zu",D33="trifft nicht zu"),"trifft nicht zu","") | L31: =VLOOKUP(O31,$C$102:$E$106,3,FALSE()) -> 1.5 | M31: =VLOOKUP(D31,$C$102:$E$106,3,FALSE()) -> 1.5 | N31: =IF(L31=M31,"",'12.lan'!$D$240&VLOOKUP(L31,$C$102:$D$106,2,FALSE())&" ("&L31&")") | O31: =IF(K31="trifft nicht zu",C106,'9. Weighting'!O24) -> 1.5
B32: B3.1 | C32: ='12.lan'!D131 -> Environmental quality of investments | D32: =C104 -> 1 | E32: =VLOOKUP(D32,$C$102:$D$106,2,FALSE()) -> medium | F32: ='12.lan'!$D$329 -> Introduce value between 0 and 10 | H32: 0 | I32: =IFERROR(J32*H32/10,0) -> 0 | J32: =IFERROR($J$31*K32/($K$32+$K$33),0) -> 71.428571 | K32: =VLOOKUP(D32,$C$102:$E$106,3,FALSE()) -> 1 | L32: =VLOOKUP(O32,$C$102:$E$106,3,FALSE()) -> 1 | M32: =VLOOKUP(D32,$C$102:$E$106,3,FALSE()) -> 1 | N32: =IF(L32=M32,"",'12.lan'!$D$240&VLOOKUP(L32,$C$102:$D$106,2,FALSE())&" ("&L32&")") | O32: =C104 -> 1
B33: B3.2 | C33: ='12.lan'!D132 -> Common Good-orientated investment | D33: =C104 -> 1 | E33: =VLOOKUP(D33,$C$102:$D$106,2,FALSE()) -> medium | F33: ='12.lan'!$D$329 -> Introduce value between 0 and 10 | H33: 0 | I33: =IFERROR(J33*H33/10,0) -> 0 | J33: =IFERROR($J$31*K33/($K$32+$K$33),0) -> 71.428571 | K33: =VLOOKUP(D33,$C$102:$E$106,3,FALSE()) -> 1 | L33: =VLOOKUP(O33,$C$102:$E$106,3,FALSE()) -> 1 | M33: =VLOOKUP(D33,$C$102:$E$106,3,FALSE()) -> 1 | N33: =IF(L33=M33,"",'12.lan'!$D$240&VLOOKUP(L33,$C$102:$D$106,2,FALSE())&" ("&L33&")") | O33: =C104 -> 1
B34: B3.3 | C34: ='12.lan'!D133 -> Negative aspect: reliance on environmentally unsafe resources | F34: ='12.lan'!$D$330 -> Introduce negative points between 0 and -200 | H34: 0 | I34: =H34*J31/50 -> 0 | J34: =-200*J31/50 -> -571.42857
B35: B4 | C35: ='12.lan'!D134 -> Ownership and co-determination | D35: =IF(K35="trifft nicht zu",C106,'9. Weighting'!P24) -> 0.5 | E35: =VLOOKUP(D35,$C$102:$D$106,2,FALSE()) -> low | F35: =IF(K35="trifft nicht zu","trifft nicht zu",'9. Weighting'!P24) -> 0.5 | H35: =IF(J35<>0,SUM(I36:I37)/J35,"-") -> 0 | I35: =IF(J35=0,0,H35*J35) -> 0 | J35: ='9. Weighting'!P23 -> 47.619048 | L35: =VLOOKUP(O35,$C$102:$E$106,3,FALSE()) -> 0.5 | M35: =VLOOKUP(D35,$C$102:$E$106,3,FALSE()) -> 0.5 | N35: =IF(L35=M35,"",'12.lan'!$D$240&VLOOKUP(L35,$C$102:$D$106,2,FALSE())&" ("&L35&")") | O35: =IF(K35="trifft nicht zu",C106,'9. Weighting'!P24) -> 0.5
B36: B4.1 | C36: ='12.lan'!D135 -> Common Good-orientated ownership structure | F36: ='12.lan'!$D$329 -> Introduce value between 0 and 10 | I36: =J36*H36/10 -> 0 | J36: =$J$35*K36/(K36) -> 47.619048 | K36: 1
B37: B4.2 | C37: ='12.lan'!D136 -> Negative aspect: hostile takeover | F37: ='12.lan'!$D$330 -> Introduce negative points between 0 and -200 | I37: =H37*J35/50 -> 0 | J37: =-200*J35/50 -> -190.47619
B38: C | C38: ='12.lan'!D137 -> Employees | D38: =L38 -> 0.5 | E38: =VLOOKUP(D38,$C$102:$D$106,2,FALSE()) -> low | H38: =IFERROR(I38/J38,0) -> -0.10916667 | I38: =I39+I44+I49+I54 -> -10.396825 | J38: =J39+J44+J49+J54 -> 95.238095 | L38: ='9. Weighting'!K51 -> 0.5 | N38: =IF(D38<>L38,'12.lan'!$D$240&VLOOKUP(L38,$C$102:$D$106,2,FALSE())&" ("&L38&")","")
B39: C1 | C39: ='12.lan'!D138 -> Human dignity in the workplace and working environment | D39: =IF(K39="trifft nicht zu",C101,'9. Weighting'!M30) -> 1 | E39: =VLOOKUP(D39,$C$102:$D$106,2,FALSE()) -> medium | F39: =IF(K39="trifft nicht zu","trifft nicht zu",'9. Weighting'!M30) -> 1 | H39: =IF(J39<>0,SUM(I40:I43)/J39,"-") -> 0.033333333 | I39: =IF(J39=0,0,H39*J39) -> 0.79365079 | J39: ='9. Weighting'!M29 -> 23.809524 | K39: =IF(AND(D40="trifft nicht zu",D41="trifft nicht zu",,D42="trifft nicht zu"),"trifft nicht zu","") | L39: =VLOOKUP(O39,$C$102:$E$106,3,FALSE()) -> 1 | M39: =VLOOKUP(D39,$C$102:$E$106,3,FALSE()) -> 1 | N39: =IF(L39=M39,"",'12.lan'!$D$240&VLOOKUP(L39,$C$102:$D$106,2,FALSE())&" ("&L39&")") | O39: =IF(K39="trifft nicht zu",C106,'9. Weighting'!M30) -> 1
B40: C1.1 | C40: ='12.lan'!D139 -> Employee-focused organisational culture | D40: =C104 -> 1 | E40: =VLOOKUP(D40,$C$102:$D$106,2,FALSE()) -> medium | F40: ='12.lan'!$D$329 -> Introduce value between 0 and 10 | H40: 1 | I40: =IFERROR(J40*H40/10,0) -> 0.79365079 | J40: =IFERROR($J$39*K40/(SUM($K$40:$K$42)),0) -> 7.9365079 | K40: =VLOOKUP(D40,$C$102:$E$106,3,FALSE()) -> 1 | L40: =VLOOKUP(O40,$C$102:$E$106,3,FALSE()) -> 1 | M40: =VLOOKUP(D40,$C$102:$E$106,3,FALSE()) -> 1 | N40: =IF(L40=M40,"",'12.lan'!$D$240&VLOOKUP(L40,$C$102:$D$106,2,FALSE())&" ("&L40&")") | O40: =C104 -> 1
B41: C1.2 | C41: ='12.lan'!D140 -> Health promotion and occupational health and safety | D41: =C104 -> 1 | E41: =VLOOKUP(D41,$C$102:$D$106,2,FALSE()) -> medium | F41: ='12.lan'!$D$329 -> Introduce value between 0 and 10 | I41: =IFERROR(J41*H41/10,0) -> 0 | J41: =IFERROR($J$39*K41/(SUM($K$40:$K$42)),0) -> 7.9365079 | K41: =VLOOKUP(D41,$C$102:$E$106,3,FALSE()) -> 1 | L41: =VLOOKUP(O41,$C$102:$E$106,3,FALSE()) -> 1 | M41: =VLOOKUP(D41,$C$102:$E$106,3,FALSE()) -> 1 | N41: =IF(L41=M41,"",'12.lan'!$D$240&VLOOKUP(L41,$C$102:$D$106,2,FALSE())&" ("&L41&")") | O41: =C104 -> 1
B42: C1.3 | C42: ='12.lan'!D141 -> Diversity and equal opportunities | D42: =C104 -> 1 | E42: =VLOOKUP(D42,$C$102:$D$106,2,FALSE()) -> medium | F42: ='12.lan'!$D$329 -> Introduce value between 0 and 10 | I42: =IFERROR(J42*H42/10,0) -> 0 | J42: =IFERROR($J$39*K42/(SUM($K$40:$K$42)),0) -> 7.9365079 | K42: =VLOOKUP(D42,$C$102:$E$106,3,FALSE()) -> 1 | L42: =VLOOKUP(O42,$C$102:$E$106,3,FALSE()) -> 1 | M42: =VLOOKUP(D42,$C$102:$E$106,3,FALSE()) -> 1 | N42: =IF(L42=M42,"",'12.lan'!$D$240&VLOOKUP(L42,$C$102:$D$106,2,FALSE())&" ("&L42&")") | O42: =C104 -> 1
B43: C1.4 | C43: ='12.lan'!D142 -> Negative aspect: unfit working conditions | F43: ='12.lan'!$D$330 -> Introduce negative points between 0 and -200 | H43: 0 | I43: =H43*J39/50 -> 0 | J43: =-200*J39/50 -> -95.238095
...

Sheet 9. Weighting
E4: MATRIX 5.0 | K4: VALUES WERTE | M4: 1) HUMAN DIGNITY | N4: 2) SOLIDARITY & JUSTICE | O4: 3) ECOLOGICAL SUSTAINABILITY | P4: 4) DEMOCRATIC CO-DETERMINATION AND TRANSPARENCY
B5: Total Sales (in Mio Euro)
B6: Total Assets (in Mio Euro)
H7: fields necessary to fill out | J7: these field contains a comment on the necesarry information for cells to be filled out or on the weighting in general
F8: STAKEHOLDER BERÜHRUNGSGGRUPPE
M9: =M15+M23+M29+M36+M42 -> 238.09524 | N9: =N15+N23+N29+N36+N42 -> 309.52381 | O9: =O15+O23+O29+O36+O42 -> 297.61905 | P9: =P15+P23+P29+P36+P42 -> 154.7619
F10: Gesamt-Ausgaben an Lieferanten / total expenditures on the supply chain | I10: ='2. Company Facts'!C7 -> 200000 | J10: A: SUPPLIERS | K10: =K49 -> 0.5 | L10: =M15+N15+O15+P15 -> 95.238095 | M10: A1 | N10: A2 | O10: A3 | P10: A4
E12: NACE | F12: Industry | G12: Product / Services Description | H12: Region | I12: Expenditures
E13: =LEFT(F13,2) -> A | F13: ='2. Company Facts'!B10 -> A - Landwirtschaft, Forstwirtschaft und Fischerei | G13: ='2. Company Facts'!C10 -> 0 | H13: ='2. Company Facts'!D10 -> EGY Ägypten | I13: ='2. Company Facts'!F10 -> 3388
E14: =LEFT(F14,2) -> Ca | F14: ='2. Company Facts'!B11 -> Ca - Food production, drinks and tobacco (C10, C11, C12) | G14: ='2. Company Facts'!C11 -> 0 | H14: ='2. Company Facts'!D11 -> AFG Afghanistan | I14: ='2. Company Facts'!F11 -> 654 | M14: ='3. Calc'!D10 -> 1 | N14: ='3. Calc'!D13 -> 1 | O14: ='3. Calc'!D17 -> 1 | P14: ='3. Calc'!D20 -> 1 | Q14: ='11.Region'!U10 -> 0
E15: =LEFT(F15,2) -> A | F15: ='2. Company Facts'!B12 -> A - Landwirtschaft, Forstwirtschaft und Fischerei | G15: ='2. Company Facts'!C12 -> 0 | H15: ='2. Company Facts'!D12 -> DZA Algerien | I15: ='2. Company Facts'!F12 -> 456 | M15: =M49 -> 23.809524 | N15: =N49 -> 23.809524 | O15: =O49 -> 23.809524 | P15: =P49 -> 23.809524
E16: =LEFT(F16,2) -> A | F16: ='2. Company Facts'!B13 -> A - Landwirtschaft, Forstwirtschaft und Fischerei | G16: ='2. Company Facts'!C13 -> 0 | H16: ='2. Company Facts'!D13 -> BGD Bangladesch | I16: ='2. Company Facts'!F13 -> 77 | M16: =IF(G69="empty",1,'3. Calc'!C104) -> 1 | N16: =IF(G69="empty",1,'3. Calc'!C104) -> 1 | O16: =IF(G69="empty",1,IFERROR(IF('11.Region'!N8>1.5,'3. Calc'!C102,IF('11.Region'!N8>1.25,'3. Calc'!C103,IF('11.Region'!N8<0.75,'3. Calc'!C105,'3. Calc'!C104))),'3. Calc'!C104)) -> 1 | P16: =IF(G69="empty",1,IF('11.Region'!I9<1.5,'3. Calc'!C105,IF('11.Region'!I9<3.26,'3. Calc'!C104,IF('11.Region'!I9<4.5,'3. Calc'!C103,'3. Calc'!C102)))) -> 1
E17: =LEFT(F17,2) -> Pl | F17: ='2. Company Facts'!B14 -> Please enter | G17: ='2. Company Facts'!C14 -> 0 | H17: ='2. Company Facts'!D14 -> 0 | I17: ='2. Company Facts'!F14 -> 0
F18: Rest | H18: ='2. Company Facts'!D15 -> QAT Katar | I18: ='2. Company Facts'!F15 -> 195425
F19: profit | I19: ='2. Company Facts'!C18 -> 456456456 | J19: B: INVESTORS | K19: =K50 -> 2 | L19: =M23+N23+O23+P23 -> 428.57143 | M19: B1 | N19: B2 | O19: B3 | P19: B4
F20: profit in % of total Sales | I20: =IFERROR(I19/I32,"-") -> 3681100.5
F21: costs of finance | I21: ='2. Company Facts'!C19 -> 266
E22: =IFERROR((G24+I24)/I23,0.2) -> 1.6904762 | F22: <-- (zugänge anlageverm.+financial assets)/total assets | G22: finance income | I22: ='2. Company Facts'!C20 -> 500 | M22: ='3. Calc'!D24 -> 1 | N22: ='3. Calc'!D28 -> 1.5 | O22: ='3. Calc'!D31 -> 1.5 | P22: ='3. Calc'!D35 -> 0.5
E23: =IFERROR(I32/I23,0.3) -> 0.2952381 | F23: <-- ratio: sales/assets | G23: total assets | I23: ='2. Company Facts'!C21 -> 420 | M23: =M50 -> 95.238095 | N23: =N50 -> 142.85714 | O23: =O50 -> 142.85714 | P23: =P50 -> 47.619048
F24: "zugänge zum anlagevermögen" | G24: ='2. Company Facts'!C22 -> 400 | H24: "invested money" | I24: ='2. Company Facts'!C23 -> 310 | M24: =IF(G69="empty",1,IFERROR(IF(H35='10. Industry'!A22,'3. Calc'!C102,IF(E23<0.1,'3. Calc'!C103,IF(E23>0.5,'3. Calc'!C105,'3. Calc'!C104))),'3. Calc'!C104)) -> 1 | N24: =IF(G69="empty",1,IFERROR(IF(I20="-",'3. Calc'!C104,IF(I20>0.1,'3. Calc'!C103,IF(I20<0.001,'3. Calc'!C106,IF(I20<0.03,'3. Calc'!C105,'3. Calc'!C104)))),'3. Calc'!C104)) -> 1.5 | O24: =IF(G69="empty",1,IFERROR(IF(H35='10. Industry'!A22,'3. Calc'!C102,IF(E22<0.1,'3. Calc'!C105,IF(E22>0.25,'3. Calc'!C103,'3. Calc'!C104))),'3. Calc'!C104)) -> 1.5 | P24: =IF(G69="empty",1,IF(H39='12.lan'!D324,'3. Calc'!C105,'3. Calc'!C104)) -> 0.5
F25: employee expenditures | I25: ='2. Company Facts'!C27 -> 5501 | J25: C: EMPLOYEES | K25: =K51 -> 0.5 | L25: =M29+N29+O29+P29 -> 95.238095 | M25: C1 | N25: C2 | O25: C3 | P25: C4
F26: number of FTE | I26: ='2. Company Facts'!C26 -> 5
G27: % employees in | H27: ='2. Company Facts'!B30 -> ETH Äthiopien | I27: ='2. Company Facts'!D30 -> 0.46
G28: % employees in | H28: ='2. Company Facts'!B31 -> BHR Bahrain | I28: ='2. Company Facts'!D31 -> 0.11 | M28: ='3. Calc'!D39 -> 1 | N28: ='3. Calc'!D44 -> 1 | O28: ='3. Calc'!D49 -> 1.5 | P28: ='3. Calc'!D54 -> 0.5
G29: % employees in | H29: ='2. Company Facts'!B32 -> 0 | I29: ='2. Company Facts'!D32 -> 0 | M29: =M51 -> 23.809524 | N29: =N51 -> 23.809524 | O29: =O51 -> 35.714286 | P29: =P51 -> 11.904762
F30: potential commuting impact | I30: ='2. Company Facts'!C33 -> 456456 | M30: =IF(G69="empty",1,'3. Calc'!C104) -> 1 | N30: =IF(G69="empty",1,'3. Calc'!C104) -> 1 | O30: =IF(G69="empty",1,IF(AND(I31='12.lan'!D53,I30<10),'3. Calc'!C105,IF(I30>25,'3. Calc'!C103,'3. Calc'!C104))) -> 1.5 | P30: =IF(G69="empty",1,IF(I26=1,'3. Calc'!C106,IF(H39='12.lan'!D324,'3. Calc'!C105,IF('11.Region'!I14>3.25,'3. Calc'!C103,'3. Calc'!C104)))) -> 0.5
F31: existence of a company canteen | I31: ='2. Company Facts'!C34 -> no
F32: total sales | I32: ='2. Company Facts'!C37 -> 124 | J32: D: CUSTOMERS | K32: 1 | L32: =M36+N36+O36+P36 -> 190.47619 | M32: D1 | N32: D2 | O32: D3 | P32: D4
H33: B2B / B2C | I33: ='2. Company Facts'!C38 -> ja
F34: Industry | G34: Product / Services Description | H34: industry | I34: % of total sales
F35: ='2. Company Facts'!B41 -> J - Information und Kommunikation | G35: ='2. Company Facts'!C41 -> 0 | H35: =LEFT(F35,2) -> J | I35: ='2. Company Facts'!D41 -> 0.87 | M35: ='3. Calc'!D60 -> 1 | N35: ='3. Calc'!D64 -> 1 | O35: ='3. Calc'!D68 -> 1 | P35: ='3. Calc'!D72 -> 1
F36: ='2. Company Facts'!B42 -> Ce - Pharmaceutical products and preparations (C21) | G36: ='2. Company Facts'!C42 -> abc | H36: =LEFT(F36,2) -> Ce | I36: ='2. Company Facts'!D42 -> 0.13 | M36: =M52 -> 47.619048 | N36: =N52 -> 47.619048 | O36: =O52 -> 47.619048 | P36: =P52 -> 47.619048
F37: ='2. Company Facts'!B43 -> Please enter | G37: ='2. Company Facts'!C43 -> 0 | H37: =LEFT(F37,2) -> Pl | I37: ='2. Company Facts'!D43 -> 0 | M37: =IF(G69="empty",1,'3. Calc'!C104) -> 1 | N37: =IF(G69="empty",1,'3. Calc'!C104) -> 1 | O37: =IF(G69="empty",1,VLOOKUP(S37,'3. Calc'!$B$102:$C$106,2,FALSE())) -> 1 | P37: =IF(G69="empty",1,IFERROR(IF(I33='12.lan'!D52,'3. Calc'!C103,'3. Calc'!C104),'3. Calc'!C104)) -> 1 | S37: =VLOOKUP('10. Industry'!J39,F49:H53,3,FALSE()) -> 1
J38: E: SOCIETY | K38: 1 | L38: =M42+N42+O42+P42 -> 190.47619 | M38: E1 | N38: E2 | O38: E3 | P38: E4
H39: =IF(AND(I26<10,OR(I32<=2000000,I23<=2000000)),'12.lan'!D324,IF(AND(I26<50,OR(I32<=10000000,I23<=10000000)),'12.lan'!D325,IF(AND(I26<250,OR(I32<=50000000,I23<=43000000)),'12.lan'!D326,'12.lan'!D327))) -> Micro-business
F40: Company Size (EU definition) | H40: =IF(AND(I26=0,I32=0,I23=0),'12.lan'!E326) -> 0
M41: ='3. Calc'!D77 -> 1 | N41: ='3. Calc'!D81 -> 1.5 | O41: ='3. Calc'!D86 -> 1 | P41: ='3. Calc'!D90 -> 0.5
M42: =M53 -> 47.619048 | N42: =N53 -> 71.428571 | O42: =O53 -> 47.619048 | P42: =P53 -> 23.809524
M43: =IF(G69="empty",1,'3. Calc'!C104) -> 1 | N43: =IF(G69="empty",1,IF(I20="-",'3. Calc'!C104,IF(I20<0.05,'3. Calc'!C105,IF(I20<0.1,'3. Calc'!C104,IF(I20>0.1,'3. Calc'!C103,'3. Calc'!C104))))) -> 1.5 | O43: =IF(G69="empty",1,VLOOKUP(S37,'3. Calc'!$B$102:$C$106,2,FALSE())) -> 1 | P43: =IF(G69="empty",1,IF(H35="B",'3. Calc'!C103,IF(H35="F",'3. Calc'!C103,IF(H39='12.lan'!D324,'3. Calc'!C105,IF(H39='12.lan'!D324,'3. Calc'!C105,'3. Calc'!C104))))) -> 0.5 | S43: =VLOOKUP('10. Industry'!L39,F49:H53,3,FALSE()) -> 1.5
M45: 1) HUMAN DIGNITY | N45: 2) COOPERATION AND SOLIDARITY | O45: 3) ECOLOGICAL SUSTAINABILITY | P45: 5) DEMOCRATIC CO-DETERMINATION AND TRANSPARENCY
...

Sheet 4. ECG-Matrix
B2: ='12.lan'!D91&" - "&'0. Intro'!B3&" "&'0. Intro'!C3 -> Common Good Balance Calculator - Version 5.06 | I2: ='12.lan'!D212 -> Note: This is not a certificate.
B3: ='12.lan'!D213 -> COMMON GOOD MATRIX
I4: ='12.lan'!D92 -> Total Balance Score: | K4: ='3. Calc'!I4 -> -389.04762 | M4: ='12.lan'!D214&" "&'3. Calc'!$J$4&'12.lan'!D215 -> of 1000 points
B5: ='12.lan'!D82&": "&'1. General'!C6&"; "&'12.lan'!D83&": "&'1. General'!C12 -> Company / Organisation: LuftGewinn; Period under review: 01.01.2019 - 31.12.2019
B7: ='12.lan'!D206 -> Values ► Stakekolders ▼ | C7: ='12.lan'!D216 -> Human dignity | G7: ='12.lan'!D217 -> Solidarity & social justice | K7: ='12.lan'!D218 -> Environmental sustainability | O7: ='12.lan'!D219 -> Transparency & co-determination
B8: ="A: "&'12.lan'!D108 -> A: Suppliers | C8: ='12.lan'!B109 -> A1: Human dignity in the supply chain | G8: ='12.lan'!B112 -> A2: Solidarity and social justice in the supply chain | K8: ='12.lan'!B116 -> A3: Environmental sustainability in the supply chain | O8: ='12.lan'!B119 -> A4: Transparency & co-determination in the supply chain
C9: ='3. Calc'!I10 -> -42.857143 | D9: ='12.lan'!$D$214 -> of | E9: ='3. Calc'!J10 -> 23.809524 | F9: ='3. Calc'!H10 -> -1.8 | G9: ='3. Calc'!I13 -> -42.857143 | H9: ='12.lan'!$D$214 -> of | I9: ='3. Calc'!J13 -> 23.809524 | J9: ='3. Calc'!H13 -> -1.8 | K9: ='3. Calc'!I17 -> 2.3809524 | L9: ='12.lan'!$D$214 -> of | M9: ='3. Calc'!J17 -> 23.809524 | N9: ='3. Calc'!H17 -> 0.1 | O9: ='3. Calc'!I20 -> 0 | P9: ='12.lan'!$D$214 -> of | Q9: ='3. Calc'!J20 -> 23.809524 | R9: ='3. Calc'!H20 -> 0
B10: ="B: "&'12.lan'!D122 -> B: Owners, equity- and financial service providers | C10: ='12.lan'!B123 -> B1: Ethical position in relation to financial resources | G10: ='12.lan'!B127 -> B2: Social position in relation to financial resources | K10: ='12.lan'!B130 -> B3: Use of funds in relation to social and environmental impacts | O10: ='12.lan'!B134&IF('9. Weighting'!I28=1,'12.lan'!D211,"") -> B4: Ownership and co-determination
C11: ='3. Calc'!I24 -> 15.873016 | D11: ='12.lan'!$D$214 -> of | E11: ='3. Calc'!J24 -> 95.238095 | F11: ='3. Calc'!H24 -> 0.16666667 | G11: ='3. Calc'!I28 -> 0 | H11: ='12.lan'!$D$214 -> of | I11: ='3. Calc'!J28 -> 142.85714 | J11: ='3. Calc'!H28 -> 0 | K11: ='3. Calc'!I31 -> 0 | L11: ='12.lan'!$D$214 -> of | M11: ='3. Calc'!J31 -> 142.85714 | N11: ='3. Calc'!H31 -> 0 | O11: ='3. Calc'!I35 -> 0 | P11: ='12.lan'!$D$214 -> of | Q11: ='3. Calc'!J35 -> 47.619048 | R11: ='3. Calc'!H35 -> 0
B12: ="C: "&'12.lan'!D137 -> C: Employees | C12: ='12.lan'!B138 -> C1: Human dignity in the workplace and working environment | G12: ='12.lan'!B143 -> C2: Self-determined working arrangements | K12: ='12.lan'!B148 -> C3: Environmentally-friendly behaviour of staff | O12: ='12.lan'!B153 -> C4: Co-determination and transparency within the organisation
C13: ='3. Calc'!I39 -> 0.79365079 | D13: ='12.lan'!$D$214 -> of | E13: ='3. Calc'!J39 -> 23.809524 | F13: ='3. Calc'!H39 -> 0.033333333 | G13: ='3. Calc'!I44 -> -0.47619048 | H13: ='12.lan'!$D$214 -> of | I13: ='3. Calc'!J44 -> 23.809524 | J13: ='3. Calc'!H44 -> -0.02 | K13: ='3. Calc'!I49 -> -10.714286 | L13: ='12.lan'!$D$214 -> of | M13: ='3. Calc'!J49 -> 35.714286 | N13: ='3. Calc'!H49 -> -0.3 | O13: ='3. Calc'!I54 -> 0 | P13: ='12.lan'!$D$214 -> of | Q13: ='3. Calc'!J54 -> 11.904762 | R13: ='3. Calc'!H54 -> 0
B14: ="D: "&'12.lan'!D158 -> D: Customers and other companies | C14: ='12.lan'!B159 -> D1: Ethical customer relations | G14: ='12.lan'!B163 -> D2: Cooperation and solidarity with other companies | K14: ='12.lan'!B167 -> D3: Impact on the environment of the use and disposal of products and services | O14: ='12.lan'!B171 -> D4: Customer participation and product transparency
C15: ='3. Calc'!I60 -> -161.90476 | D15: ='12.lan'!$D$214 -> of | E15: ='3. Calc'!J60 -> 47.619048 | F15: ='3. Calc'!H60 -> -3.4 | G15: ='3. Calc'!I64 -> 0 | H15: ='12.lan'!$D$214 -> of | I15: ='3. Calc'!J64 -> 47.619048 | J15: ='3. Calc'!H64 -> 0 | K15: ='3. Calc'!I68 -> 0 | L15: ='12.lan'!$D$214 -> of | M15: ='3. Calc'!J68 -> 47.619048 | N15: ='3. Calc'!H68 -> 0 | O15: ='3. Calc'!I72 -> -52.380952 | P15: ='12.lan'!$D$214 -> of | Q15: ='3. Calc'!J72 -> 47.619048 | R15: ='3. Calc'!H72 -> -1.1
B16: ="E: "&'12.lan'!D175 -> E: Social environment | C16: ='12.lan'!B176 -> E1: Purpose of products and services and their effects on society | G16: ='12.lan'!B180 -> E2: Contribution to the community | K16: ='12.lan'!B185 -> E3: Reduction of environmental impact | O16: ='12.lan'!B189 -> E4: Social co-determination and transparency
C17: ='3. Calc'!I77 -> -95.238095 | D17: ='12.lan'!$D$214 -> of | E17: ='3. Calc'!J77 -> 47.619048 | F17: ='3. Calc'!H77 -> -2 | G17: ='3. Calc'!I81 -> 0 | H17: ='12.lan'!$D$214 -> of | I17: ='3. Calc'!J81 -> 71.428571 | J17: ='3. Calc'!H81 -> 0 | K17: ='3. Calc'!I86 -> -2.8571429 | L17: ='12.lan'!$D$214 -> of | M17: ='3. Calc'!J86 -> 47.619048 | N17: ='3. Calc'!H86 -> -0.06 | O17: ='3. Calc'!I90 -> 1.1904762 | P17: ='12.lan'!$D$214 -> of | Q17: ='3. Calc'!J90 -> 23.809524 | R17: ='3. Calc'!H90 -> 0.05
B19: ='12.lan'!D46 -> Please note that the format of the numbers in the matrix is rounded

Sheet 5. Values
B2: ='12.lan'!D91&" - "&'0. Intro'!B3&" "&'0. Intro'!C3 -> Common Good Balance Calculator - Version 5.06
B3: ='12.lan'!D241&'1. General'!C6 -> Values star for LuftGewinn
B17: ='12.lan'!D221 -> BALANCE OVERVIEW
B18: ='12.lan'!D216 -> Human dignity | C18: ='4. ECG-Matrix'!C9+'4. ECG-Matrix'!C11+'4. ECG-Matrix'!C13+'4. ECG-Matrix'!C15+'4. ECG-Matrix'!C17 -> -283.33333 | D18: ='12.lan'!$D$214 -> of | E18: ='4. ECG-Matrix'!E9+'4. ECG-Matrix'!E11+'4. ECG-Matrix'!E13+'4. ECG-Matrix'!E15+'4. ECG-Matrix'!E17 -> 238.09524 | F18: =C18/E18 -> -1.19 | G18: =IF(F18<0,0,F18) -> 0
B19: ='12.lan'!D217 -> Solidarity & social justice | C19: ='4. ECG-Matrix'!G9+'4. ECG-Matrix'!G11+'4. ECG-Matrix'!G13+'4. ECG-Matrix'!G15+'4. ECG-Matrix'!G17 -> -43.333333 | D19: ='12.lan'!$D$214 -> of | E19: ='4. ECG-Matrix'!I9+'4. ECG-Matrix'!I11+'4. ECG-Matrix'!I13+'4. ECG-Matrix'!I15+'4. ECG-Matrix'!I17 -> 309.52381 | F19: =C19/E19 -> -0.14 | G19: =IF(F19<0,0,F19) -> 0
B20: ='12.lan'!D218 -> Environmental sustainability | C20: ='4. ECG-Matrix'!K9+'4. ECG-Matrix'!K11+'4. ECG-Matrix'!K13+'4. ECG-Matrix'!K15+'4. ECG-Matrix'!K17 -> -11.190476 | D20: ='12.lan'!$D$214 -> of | E20: ='4. ECG-Matrix'!M9+'4. ECG-Matrix'!M11+'4. ECG-Matrix'!M13+'4. ECG-Matrix'!M15+'4. ECG-Matrix'!M17 -> 297.61905 | F20: =C20/E20 -> -0.0376 | G20: =IF(F20<0,0,F20) -> 0
B21: ='12.lan'!D219 -> Transparency & co-determination | C21: ='4. ECG-Matrix'!O9+'4. ECG-Matrix'!O11+'4. ECG-Matrix'!O13+'4. ECG-Matrix'!O15+'4. ECG-Matrix'!O17 -> -51.190476 | D21: ='12.lan'!$D$214 -> of | E21: ='4. ECG-Matrix'!Q9+'4. ECG-Matrix'!Q11+'4. ECG-Matrix'!Q13+'4. ECG-Matrix'!Q15+'4. ECG-Matrix'!Q17 -> 154.7619 | F21: =C21/E21 -> -0.33076923 | G21: =IF(F21<0,0,F21) -> 0
B22: ='12.lan'!D228 -> TOTAL | C22: ='3. Calc'!I4 -> -389.04762 | D22: ='12.lan'!$D$214 -> of | E22: ='3. Calc'!J4 -> 1000 | F22: =C22/E22 -> -0.38904762

Sheet 6. Stakeholder
B2: ='12.lan'!D91&" - "&'0. Intro'!B3&" "&'0. Intro'!C3 -> Common Good Balance Calculator - Version 5.06
B3: ='12.lan'!D242&'1. General'!C6 -> Group star for LuftGewinn
B17: ='12.lan'!D221 -> BALANCE OVERVIEW
B18: ='12.lan'!D108 -> Suppliers | C18: ='3. Calc'!I9 -> -83.333333 | D18: ='12.lan'!$D$214 -> of | E18: ='3. Calc'!J9 -> 95.238095 | F18: =C18/E18 -> -0.875 | G18: =IF(F18<0,0,F18) -> 0
B19: ='12.lan'!D122 -> Owners, equity- and financial service providers | C19: ='3. Calc'!I23 -> 15.873016 | D19: ='12.lan'!$D$214 -> of | E19: ='3. Calc'!J23 -> 428.57143 | F19: =C19/E19 -> 0.037037037 | G19: =IF(F19<0,0,F19) -> 0.037037037
B20: ='12.lan'!D137 -> Employees | C20: ='3. Calc'!I38 -> -10.396825 | D20: ='12.lan'!$D$214 -> of | E20: ='3. Calc'!J38 -> 95.238095 | F20: =C20/E20 -> -0.10916667 | G20: =IF(F20<0,0,F20) -> 0
B21: ='12.lan'!D158 -> Customers and other companies | C21: ='3. Calc'!I59 -> -214.28571 | D21: ='12.lan'!$D$214 -> of | E21: ='3. Calc'!J59 -> 190.47619 | F21: =C21/E21 -> -1.125 | G21: =IF(F21<0,0,F21) -> 0
B22: ='12.lan'!D175 -> Social environment | C22: ='3. Calc'!I76 -> -96.904762 | D22: ='12.lan'!$D$214 -> of | E22: ='3. Calc'!J76 -> 190.47619 | F22: =C22/E22 -> -0.50875 | G22: =IF(F22<0,0,F22) -> 0
B23: ='12.lan'!D228 -> TOTAL | C23: ='3. Calc'!I4 -> -389.04762 | D23: ='12.lan'!$D$214 -> of | E23: ='3. Calc'!J4 -> 1000 | F23: =C23/E23 -> -0.38904762

Sheet 7. Topics
B2: ='12.lan'!D91&" - "&'0. Intro'!B3&" "&'0. Intro'!C3 -> Common Good Balance Calculator - Version 5.06
B3: ='12.lan'!D243&'1. General'!C6 -> Theme star for LuftGewinn
B17: ='12.lan'!D221 -> BALANCE OVERVIEW
B18: A1 | C18: ='4. ECG-Matrix'!C9 -> -42.857143 | D18: ='12.lan'!$D$214 -> of | E18: ='4. ECG-Matrix'!E9 -> 23.809524 | F18: =C18/E18 -> -1.8 | G18: =IF(F18<0,0,F18) -> 0
B19: A2 | C19: ='4. ECG-Matrix'!G9 -> -42.857143 | D19: ='12.lan'!$D$214 -> of | E19: ='4. ECG-Matrix'!I9 -> 23.809524 | F19: =C19/E19 -> -1.8 | G19: =IF(F19<0,0,F19) -> 0
B20: A3 | C20: ='4. ECG-Matrix'!K9 -> 2.3809524 | D20: ='12.lan'!$D$214 -> of | E20: ='4. ECG-Matrix'!M9 -> 23.809524 | F20: =C20/E20 -> 0.1 | G20: =IF(F20<0,0,F20) -> 0.1
B21: A4 | C21: ='4. ECG-Matrix'!O9 -> 0 | D21: ='12.lan'!$D$214 -> of | E21: ='4. ECG-Matrix'!Q9 -> 23.809524 | F21: =C21/E21 -> 0 | G21: =IF(F21<0,0,F21) -> 0
B22: B1 | C22: ='4. ECG-Matrix'!C11 -> 15.873016 | D22: ='12.lan'!$D$214 -> of | E22: ='4. ECG-Matrix'!E11 -> 95.238095 | F22: =C22/E22 -> 0.16666667 | G22: =IF(F22<0,0,F22) -> 0.16666667
B23: B2 | C23: ='4. ECG-Matrix'!G11 -> 0 | D23: ='12.lan'!$D$214 -> of | E23: ='4. ECG-Matrix'!I11 -> 142.85714 | F23: =C23/E23 -> 0 | G23: =IF(F23<0,0,F23) -> 0
B24: B3 | C24: ='4. ECG-Matrix'!K11 -> 0 | D24: ='12.lan'!$D$214 -> of | E24: ='4. ECG-Matrix'!M11 -> 142.85714 | F24: =C24/E24 -> 0 | G24: =IF(F24<0,0,F24) -> 0
B25: B4 | C25: ='4. ECG-Matrix'!O11 -> 0 | D25: ='12.lan'!$D$214 -> of | E25: ='4. ECG-Matrix'!Q11 -> 47.619048 | F25: =C25/E25 -> 0 | G25: =IF(F25<0,0,F25) -> 0
B26: C1 | C26: ='4. ECG-Matrix'!C13 -> 0.79365079 | D26: ='12.lan'!$D$214 -> of | E26: ='4. ECG-Matrix'!E13 -> 23.809524 | F26: =C26/E26 -> 0.033333333 | G26: =IF(F26<0,0,F26) -> 0.033333333
B27: C2 | C27: ='4. ECG-Matrix'!G13 -> -0.47619048 | D27: ='12.lan'!$D$214 -> of | E27: ='4. ECG-Matrix'!I13 -> 23.809524 | F27: =C27/E27 -> -0.02 | G27: =IF(F27<0,0,F27) -> 0
B28: C3 | C28: ='4. ECG-Matrix'!K13 -> -10.714286 | D28: ='12.lan'!$D$214 -> of | E28: ='4. ECG-Matrix'!M13 -> 35.714286 | F28: =C28/E28 -> -0.3 | G28: =IF(F28<0,0,F28) -> 0
B29: C4 | C29: ='4. ECG-Matrix'!O13 -> 0 | D29: ='12.lan'!$D$214 -> of | E29: ='4. ECG-Matrix'!Q13 -> 11.904762 | F29: =C29/E29 -> 0 | G29: =IF(F29<0,0,F29) -> 0
B30: D1 | C30: ='4. ECG-Matrix'!C15 -> -161.90476 | D30: ='12.lan'!$D$214 -> of | E30: ='4. ECG-Matrix'!E15 -> 47.619048 | F30: =C30/E30 -> -3.4 | G30: =IF(F30<0,0,F30) -> 0
B31: D2 | C31: ='4. ECG-Matrix'!G15 -> 0 | D31: ='12.lan'!$D$214 -> of | E31: ='4. ECG-Matrix'!I15 -> 47.619048 | F31: =C31/E31 -> 0 | G31: =IF(F31<0,0,F31) -> 0
B32: D3 | C32: ='4. ECG-Matrix'!K15 -> 0 | D32: ='12.lan'!$D$214 -> of | E32: ='4. ECG-Matrix'!M15 -> 47.619048 | F32: =C32/E32 -> 0 | G32: =IF(F32<0,0,F32) -> 0
B33: D4 | C33: ='4. ECG-Matrix'!O15 -> -52.380952 | D33: ='12.lan'!$D$214 -> of | E33: ='4. ECG-Matrix'!Q15 -> 47.619048 | F33: =C33/E33 -> -1.1 | G33: =IF(F33<0,0,F33) -> 0
B34: E1 | C34: ='4. ECG-Matrix'!C17 -> -95.238095 | D34: ='12.lan'!$D$214 -> of | E34: ='4. ECG-Matrix'!E17 -> 47.619048 | F34: =C34/E34 -> -2 | G34: =IF(F34<0,0,F34) -> 0
B35: E2 | C35: ='4. ECG-Matrix'!G17 -> 0 | D35: ='12.lan'!$D$214 -> of | E35: ='4. ECG-Matrix'!I17 -> 71.428571 | F35: =C35/E35 -> 0 | G35: =IF(F35<0,0,F35) -> 0
B36: E3 | C36: ='4. ECG-Matrix'!K17 -> -2.8571429 | D36: ='12.lan'!$D$214 -> of | E36: ='4. ECG-Matrix'!M17 -> 47.619048 | F36: =C36/E36 -> -0.06 | G36: =IF(F36<0,0,F36) -> 0
B37: E4 | C37: ='4. ECG-Matrix'!O17 -> 1.1904762 | D37: ='12.lan'!$D$214 -> of | E37: ='4. ECG-Matrix'!Q17 -> 23.809524 | F37: =C37/E37 -> 0.05 | G37: =IF(F37<0,0,F37) -> 0.05
B38: ='12.lan'!D228 -> TOTAL | C38: ='3. Calc'!I4 -> -389.04762 | D38: ='12.lan'!$D$214 -> of | E38: ='3. Calc'!J4 -> 1000 | F38: =C38/E38 -> -0.38904762

Sheet 8. Descr.Weighting
A1: ='12.lan'!D91&" - "&'0. Intro'!B3&" "&'0. Intro'!C3 -> Common Good Balance Calculator - Version 5.06
A2: ='12.lan'!D204 -> Description of the weighting model
A4: ='12.lan'!D208 -> General | C4: ='12.lan'!D244 -> The allocation of equal and fixed scores for all companies has been the subject of much discussion within the Matrix-development team during the past few years. Outside sources have also raised many questions and provided feedback. Untill now, the way points are distributed for themes has been the same for all companies (with the exception of one-person companies), regardless of company size, industry and other parameters (regional background, B2B versus B2C, etc.). However, these variables may well have an effect on the relevance to and effect on the common good.For example, the supply chain of an electronics trading company (A1-A4) is more significant than for a mining company, which, in turn, leaves a huge, direct environmental impact, amongst other things (E3). The new weighting model addresses these issues and highlights the significant factors. A survey on the changes was conducted, with feedback clearly favouring a new approach.
A5: ='12.lan'!D207 -> Stakekolders & values | C5: ='12.lan'!D245 -> For the weighting of three stakeholder groups, A) suppliers, B) investors and C) employees, the matrix takes into account the following financial flows to these stakeholders: A) procurement expenditure, B) profit and borrowing costs C) wages and salaries. We are aware of the limited significance attached to money in the current matrix and have plans for how this can be improved in the future. At the same time, this information is readily available in companies' financial balance sheets, and easily meets the needs of many companies. Since taxes and borrowing costs are included in procurement expenditure, these account for only 50% of the weighting.
A6: ='12.lan'!D205 -> Themes | C6: ='12.lan'!D246 -> There are also criteria for the weighting of the themes, for example a company's size or industry or the relevant local employment law. The United Nations' International Standard Industrial Classification of All Economic Activities (ISIC Rev.4) is used for all industry sector definitions. For size classification, definitions as set out by the EU are used. The table below summarises the current weighting factors (as at May 2017):
A7: A1 | C7: -
A8: A2 | C8: ='12.lan'!D248 -> -
A9: A3 | C9: ='12.lan'!D249 -> The weighting of this theme is dependent on the environmental effect of the supplier's sector (see sheet “Industry").
A10: A4 | C10: ='12.lan'!D250 -> The weighting of this theme is dependent on co-determination rights in the countries of the most important supply industries (based on the ILUC index of the International Labour Union).
A11: B1 | C11: ='12.lan'!D251 -> The weighting of this theme depends on the ratio turnover to the balance sheet total.
A12: B2 | C12: ='12.lan'!D252 -> The weighting of this theme depends on the ratio profit to turnover
A13: B3 | C13: ='12.lan'!D253 -> The weighting of this theme is dependent on additions to fixed-assets and financial assets in relation to the balance sheet total.
A14: B4 | C14: ='12.lan'!D254 -> The weighting of this theme is dependent on the size of the company.
A15: C1 | C15: ='12.lan'!D255 -> -
A16: C2 | C16: ='12.lan'!D256 -> -
A17: C3 | C17: ='12.lan'!D257 -> The weighting of this theme is dependent on the existence of a canteen for most of the employees as well as an (estimated) average commute to work.
A18: C4 | C18: ='12.lan'!D258 -> The weighting of this theme is dependent on company size and co-determination rights in the countries of the most important supply industries (based on the ILUC index of the International Labour Union).
A19: D1 | C19: ='12.lan'!D259 -> -
... A26: E4 | C26: ='12.lan'!D266 -> The weighting of this theme depends on the company size and the industry sector.

Sheet 9. Change-Management
A1: Version | B1: Changes
A2: 5.02 | B2: Spanish, Italian and English added
A3: 5.03 | B3: Change format of numbers so it works globally. There were some problems in Switzerland
A4: 5.04 | B4: Add possibility of changing the weighting by stakeholder (not only themes and aspects)
A5: 5.05 | B5: Update ITUC index and PPP index for weighting Delete rounding in some formulas. The rounding should be visible but the number stays so that the calculations are not affected. Info added about the rounding. French added
A6: 5.06 | B6: Wrong formula while considering the size of the company for the weighting in B4, C4 and E4. If there is no data in Company Facts, weighting is equally weighted. Pink conditional formatting when "canteen" and "b2b/c" field in company facts is zero. Improve editing of new languages (consistency in formulas is assured)

Sheet 10. Industry
A1: INDUSTRY WEIGHTING - COMMON GOOD MATRIX
B2: INDUSTRY | E2: A1 -social risks in the Supply Chain | G2: A3 -ecological sustainability in the Supply Chain | I2: D3 - Ecological Design of products and services | K2: E3 - Reduction of Environmental Impact | M2: E4 - Social transparency and co- determination | O2: A3 - Ecologicla Supply Chain Risk
B3: (based UN International Standard Industrial Classification of All Economic Activities, Rev.4 -http://unstats.un.org/unsd/cr/registry/regcst.asp?Cl=27) | E3: weighting | F3: argumentation: based on the social risks in the industry | G3: weighting | H3: argumentation: based on ecological impact on the planterary boundaries in the supply cahin (studies and the use of quantitative models - e.g. ecological footprint - will be applied herefor) | I3: weighting | J3: argumentation: based on the products / service impact on the planterary boundaries in the use phase (studies and the use of quantitative models - e.g. ecological footprint - will be applied herefor) | K3: weighting | L3: argumentation: based on the sectors direct impact in the production phase on the planterary boundaries (studies and the use of quantitative models will be applied herefor); e.g. sehr hoch: The sector has a major impact of various planetary boundaries | M3: weighting | N3: argumentation: the weighting is depending on the impact the industry has particularly on the adjacent environment | P3: weighting | Q3: argumentation: based on the sectors direct impact in the production phase on the planterary boundaries (studies and the use of quantitative models will be applied herefor) sehr hoch: The sector has a major impact of various planetary boundaries
A4: A | B4: ='12.lan'!D268 -> A - agriculture, forestry management, fishing industry | E4: sehr hoch | H4: ist E3? | I4: mittel | J4: the main impacts are in the production phase | K4: sehr hoch | L4: major direct impact on various planetary boundaries in the production (climate change, N/P-cycle, biodiversity, land-use-change) | M4: mittel | P4: sehr hoch
A5: B | B5: ='12.lan'!D269 -> B - Mining and quarrying | E5: sehr hoch | I5: mittel | K5: sehr hoch | L5: major impact on eco-systems | M5: sehr hoch | P5: sehr hoch
A6: C | B6: ='12.lan'!D270 -> C - Manufacturing industries (not further specified) | E6: hoch | I6: mittel | K6: hoch | L6: Please note: This industry is very heterogen. | M6: hoch | P6: hoch
A7: Ca | B7: ='12.lan'!D271 -> Ca - Food production, drinks and tobacco (C10, C11, C12) | E7: sehr hoch | I7: mittel | K7: mittel | M7: mittel | P7: sehr hoch
A8: Cb | B8: ='12.lan'!D272 -> Cb - Textile production, clothing, leather and leather products (C13, C14, C15) | E8: sehr hoch | I8: mittel | K8: hoch | M8: mittel | P8: sehr hoch
A9: Cc | B9: ='12.lan'!D273 -> Cc - Paper and forest products, also printed matter (C16, C17, C18) | E9: hoch | I9: mittel | K9: hoch | M9: mittel | P9: sehr hoch
A10: Cd | B10: ='12.lan'!D274 -> Cd - Production of petrochemical products and plastics (C19, C20;C22) | E10: sehr hoch | I10: mittel | K10: hoch | M10: hoch | P10: sehr hoch
A11: Ce | B11: ='12.lan'!D275 -> Ce - Pharmaceutical products and preparations (C21) | E11: mittel | I11: hoch | J11: residues for some pharmaproducts critical | K11: hoch | M11: hoch | P11: hoch
A12: Cf | B12: ='12.lan'!D276 -> Cf - Production of non-metallic minerals (C23) | E12: hoch | I12: mittel | K12: hoch | M12: hoch | P12: hoch
A13: Cg | B13: ='12.lan'!D277 -> Cg - Production of metal and metallic products (excl. machines and equipment) (C24, C25) | E13: sehr hoch | I13: mittel | K13: hoch | M13: hoch | P13: sehr hoch
A14: Ch | B14: ='12.lan'!D278 -> Ch - Production of electronic equipment, instruments and components as well as computers (C26, C27, C28) | E14: sehr hoch | I14: hoch | K14: hoch | M14: hoch | P14: sehr hoch
A15: D | B15: ='12.lan'!D279 -> D - Electric, Gas, Steam and Refrigeration | E15: mittel | I15: mittel | K15: sehr hoch | L15: major impact on climate change | M15: hoch | P15: sehr hoch
A16: E | B16: ='12.lan'!D280 -> E - Water supply, waste management | E16: mittel | I16: hoch | K16: hoch | M16: hoch | P16: mittel
A17: F | B17: ='12.lan'!D281 -> F - Construction industry | E17: sehr hoch | I17: sehr hoch | K17: sehr hoch | L17: major impact on climate change (see d3) and impacting land-use-change | M17: sehr hoch | P17: sehr hoch
A18: G | B18: ='12.lan'!D282 -> G - Wholesale and retail | E18: mittel | I18: sehr hoch | K18: mittel | M18: mittel | P18: hoch
A19: H | B19: ='12.lan'!D283 -> H - Transport and warehousing | E19: mittel | I19: mittel | K19: sehr hoch | M19: mittel | P19: hoch
A20: I | B20: ='12.lan'!D284 -> I - Accommodation and catering | E20: hoch | I20: mittel | K20: hoch | M20: mittel | P20: hoch
A21: J | B21: ='12.lan'!D285 -> J - Information and Communication | E21: mittel | I21: mittel | K21: hoch | M21: mittel | P21: hoch
A22: K | B22: ='12.lan'!D286 -> K - Financial services | E22: mittel | I22: sehr hoch | K22: mittel | M22: mittel | P22: mittel
A23: L | B23: ='12.lan'!D287 -> L - Real estate | E23: mittel | I23: sehr hoch | K23: mittel | M23: mittel | P23: hoch
A24: M | B24: ='12.lan'!D288 -> M - Professional, technical and scientific services | E24: mittel | I24: mittel | K24: mittel | M24: mittel | P24: mittel
A25: N | B25: ='12.lan'!D289 -> N - Administrative and support services | E25: mittel | I25: mittel | K25: mittel | M25: mittel | P25: mittel
A26: O | B26: ='12.lan'!D290 -> O - Public administration; defence; social security | E26: mittel | I26: mittel | K26: mittel | M26: mittel | P26: mittel
A27: P | B27: ='12.lan'!D291 -> P - Education | E27: mittel | I27: mittel | K27: mittel | M27: mittel | P27: mittel
A28: Q | B28: ='12.lan'!D292 -> Q - Health and social work | E28: mittel | I28: mittel | K28: mittel | M28: mittel | P28: mittel
A29: R | B29: ='12.lan'!D293 -> R - Art, education and leisure | E29: mittel | I29: mittel | K29: mittel | M29: mittel | P29: mittel
... A32: U | B32: ='12.lan'!D296 -> U - Extraterritorial organisations and bodies | E32: mittel | I32: mittel | K32: mittel | M32: mittel | P32: mittel
A34: ='9. Weighting'!H35 -> J | B34: Branche 1 | C34: ='9. Weighting'!I35 -> 0.87 | I34: =IFERROR(VLOOKUP(A34,'10. Industry'!$A$4:$O$32,9,FALSE()),"mittel") -> mittel | J34: =VLOOKUP(I34,'9. Weighting'!$F$49:$H$53,3,FALSE()) -> 1 | K34: =IFERROR(VLOOKUP(A34,'10. Industry'!$A$4:$O$32,11,FALSE()),"mittel") -> hoch | L34: =VLOOKUP(K34,'9. Weighting'!$F$49:$H$53,3,FALSE()) -> 1.5
A35: ='9. Weighting'!H36 -> Ce | B35: Branche 2 | C35: ='9. Weighting'!I36 -> 0.13 | I35: =IFERROR(VLOOKUP(A35,'10. Industry'!$A$4:$O$32,9,FALSE()),"mittel") -> hoch | J35: =VLOOKUP(I35,'9. Weighting'!$F$49:$H$53,3,FALSE()) -> 1.5 | K35: =IFERROR(VLOOKUP(A35,'10. Industry'!$A$4:$O$32,11,FALSE()),"mittel") -> hoch | L35: =VLOOKUP(K35,'9. Weighting'!$F$49:$H$53,3,FALSE()) -> 1.5
